Workbook

Sheet Hướng dẫn
A1: BACKLOG DỰ ÁN ĐỐI SOÁT HÓA ĐƠN — NHÓM FANTASTIC4
A3: Mục đích | B3: Một chỗ duy nhất để cả nhóm xem ai đang làm gì, xong đến đâu, đang vướng ở đâu. Việc lấy từ docs/TEAM_PLAN.md mục 3.
A4: Mỗi người sửa gì | B4: Chỉ sửa các ô NỀN VÀNG trên sheet Backlog: Trạng thái, % xong, Hạn, Link PR / bằng chứng, Ghi chú / vướng mắc, Cập nhật lần cuối. Các cột khác do Huy (PM) sửa.
A5: Khi nào cập nhật | B5: Trước buổi họp nhóm, và ngay khi một việc đổi trạng thái. Cập nhật xong thì ghi ngày vào cột Cập nhật lần cuối.
A6: Thêm việc mới | B6: Thêm dòng cuối bảng, ID theo người: U/P/F cho Huy, D cho Dương, H cho Hoàn, G cho Giáp — số tiếp theo. Báo Huy để khớp với TEAM_PLAN.
A8: TRẠNG THÁI
A9: Chưa làm | B9: Chưa bắt đầu.
A10: Đang làm | B10: Đang code hoặc đang viết. Ghi % xong ước lượng.
A11: Chờ review | B11: Đã có PR hoặc tài liệu, chờ người khác xem. Dán link vào cột Link PR.
A12: Bị chặn | B12: Không làm tiếp được vì chờ người khác hoặc chờ quyết định. BẮT BUỘC ghi lý do và chờ ai vào cột Ghi chú.
A13: Xong | B13: Đạt đúng cột Điều kiện xong — không phải "code chạy trên máy em".
A15: ƯU TIÊN
A16: M | B16: Bắt buộc cho MVP. Trễ thì báo ngay trong họp nhóm.
A17: S | B17: Nên có. Bị cắt đầu tiên khi trễ tiến độ.
A18: Sau | B18: Sau MVP. Chưa làm trong 5 tuần.
A20: Sheet Tuần 1 | B20: Việc cụ thể của tuần 1, mỗi việc có con số cần đạt. Làm xong ghi Kết quả thực tế và chọn Đạt hoặc Chưa đạt. Việc nào cũng trỏ về ID trong Backlog.
A21: Sheet Tổng quan | B21: Tự đếm theo người và theo trạng thái — không cần sửa.
A22: Sheet Họp tuần | B22: Mỗi buổi họp một dòng. Huy dùng sheet này để viết báo cáo tuần (P1). Dòng đầu là ví dụ, xóa khi dùng thật.
A23: Nguồn | B23: docs/TEAM_PLAN.md (mục 3, 4, 5), docs/PRD.md. Việc U5, F8, G9 là việc mới ngày 27/09/2026 — cần thêm vào TEAM_PLAN.

Sheet Tuần 1
A1: KẾ HOẠCH TUẦN 1
A2: Xong tuần 1 khi: 50 hóa đơn XML đi từ tải lên đến EXTRACTED với độ chính xác 100% · 80 bộ dữ liệu có đáp án (50 khớp + 30 lệch) · có số nền thời gian đối soát thủ công · prototype chạy kịch bản mới không còn bút toán · 3 quyết định W1-C1 đến W1-C3 đã chốt.
A3: Tiến độ | B3: =COUNTIF($G$6:$G$37,"Xong")&" / "&COUNTIF($A$6:$A$37,"W1-*")&" việc xong" | E3: ="Bị chặn: "&COUNTIF($G$6:$G$37,"Bị chặn")&" · Đạt con số: "&COUNTIF($I$6:$I$37,"Đạt")
A5: ID | B5: Hạng mục | C5: Việc | D5: Người làm | E5: Con số cần đạt | F5: Cách kiểm | G5: Trạng thái | H5: Kết quả thực tế | I5: Đạt? | J5: Liên quan backlog
A6: DỮ LIỆU — có đáp án thì mới đo được
A7: W1-D1 | B7: Dữ liệu | C7: Bộ sinh dữ liệu bản đầu: XML hóa đơn + PO + phiếu nhập khớp hoàn toàn | D7: Hoàn | E7: 50 bộ | F7: Mỗi bộ có file đáp án; parser XML đọc được cả 50 | G7: Chưa làm | J7: H1
A8: W1-D2 | B8: Dữ liệu | C8: Bộ có lệch cài sẵn, mỗi bộ ghi mã ngoại lệ đúng | D8: Hoàn | E8: 30 bộ, phủ ≥ 10 mã (PRC-01, PRC-02, QTY-01, QTY-02, TAX-02, TAX-04, DOC-01, DOC-02, ITM-01, FRD-01) | F8: Đếm mã có trong đáp án | G8: Chưa làm | J8: H1
A9: W1-D3 | B9: Dữ liệu | C9: Ảnh scan có đáp án cho việc so sánh đường đọc | D9: Dương | E9: 30 file: 20 render từ XML (có nhiễu) + 10 cào từ mạng | F9: Mỗi file có đáp án các trường đầu hóa đơn và dòng hàng | G9: Chưa làm | J9: D8
A10: W1-D4 | B10: Dữ liệu | C10: Hóa đơn cào từ mạng, ghi nguồn từng file | D10: Dương | E10: 20 file, trong đó ≥ 3 file nhiều trang | F10: Bảng nguồn: link, loại (XML/PDF/ảnh), số trang | G10: Chưa làm | J10: D8
A11: W1-D5 | B11: Dữ liệu | C11: Bộ MST để test | D11: Hoàn | E11: 20 MST: 10 đúng (công khai), 10 sai một chữ số hoặc đảo hai chữ số | F11: Test chạy qua stdnum.vn.mst | G11: Chưa làm | J11: H2
A12: W1-D6 | B12: Dữ liệu | C12: Xin mentor 2–3 file hóa đơn mẫu (đã nhắc lại, cho sẵn 3 lựa chọn). Hạn trả lời: thứ 4, 30/09/2026. Quá hạn hoặc bị từ chối → phương án B: dữ liệu sinh (W1-D1, W1-D2) và mẫu cào (W1-D4) | D12: Huy | E12: 2–3 file, hoặc mentor xác nhận dữ liệu sinh giống hóa đơn thật | F12: Có trả lời bằng văn bản; file thật chỉ để trên máy, không commit. Không xóa dòng này — ghi kết quả vào báo cáo tuần | G12: Chưa làm | J12: P3
A13: ĐO CHỈ SỐ — tuần 1 chỉ lấy số nền, chưa cần đạt mục tiêu cuối
A14: W1-M1 | B14: Đo chỉ số | C14: Độ chính xác trường XML trên bộ W1-D1 | D14: Dương | E14: 100% (50/50 hóa đơn, mọi trường) | F14: Chạy harness, so với đáp án | G14: Chưa làm | J14: D2, G7
A15: W1-M2 | B15: Đo chỉ số | C15: Thử nhanh Gemini Flash-Lite mức MEDIUM trên 10 file scan | D15: Dương | E15: Ghi 4 số: độ chính xác trường tiền, tỉ lệ sai mà không gắn cờ, chi phí/trang (kỳ vọng ≈ $0,0015), thời gian/trang (< 15 giây) | F15: Bảng kết quả trong eval/results/ | G15: Chưa làm | J15: D1
A16: W1-M3 | B16: Đo chỉ số | C16: Ghi chi phí mọi lần gọi mô hình | D16: Giáp | E16: 100% lời gọi có org_id, tokens, cost_usd, duration_ms | F16: Truy vấn bảng ai_calls sau khi chạy W1-M2 | G16: Chưa làm | J16: G5
A17: W1-M4 | B17: Đo chỉ số | C17: Số nền: đối soát thủ công mất bao lâu | D17: Huy | E17: 10 hóa đơn, bấm giờ → số phút mỗi hóa đơn | F17: Mốc để chứng minh mục tiêu giảm 50% ở tuần 4 | G17: Chưa làm | J17: U3
A18: W1-M5 | B18: Đo chỉ số | C18: Recall khớp dòng chỉ bằng luật L0–L2, chưa dùng AI | D18: Hoàn | E18: Ghi con số trên 30 bộ W1-D2 — chưa đặt mục tiêu | F18: Harness, so với đáp án | G18: Chưa làm | J18: H3
A19: PROTOTYPE — cập nhật theo quyết định mới
A20: W1-P1 | B20: Prototype | C20: Bỏ tab Bút toán, thay bằng Tóm tắt duyệt; trạng thái cuối là Đã xuất cho kế toán | D20: Huy | E20: 0 chỗ còn chữ "bút toán" hoặc tài khoản Nợ, Có | F20: Tìm chữ trong index.html | G20: Chưa làm | J20: F8
A21: W1-P2 | B21: Prototype | C21: Thêm hóa đơn mẫu cho các ca mới: dòng KCT có tiền thuế, 8% sau 31/12/2026, dòng chiết khấu, hóa đơn bị trả lại | D21: Huy | E21: Từ 6 lên ≥ 9 hóa đơn mẫu, phủ ≥ 10 mã ngoại lệ (hiện 5) | F21: Đếm trong seed() | G21: Chưa làm | J21: F8
A22: W1-P3 | B22: Prototype | C22: Hiện mục "Thông tin khác" (extras) ở màn chi tiết | D22: Huy | E22: ≥ 1 hóa đơn mẫu có extras | F22: Mở màn chi tiết thấy mục này | G22: Chưa làm | J22: PRD F2.11
A23: W1-P4 | B23: Prototype | C23: Tách lời gọi dữ liệu thành ES module, trả đúng hình dạng API ở PRD §8 | D23: Huy | E23: Giao diện không còn đọc seed() trực tiếp | F23: Đổi sang API thật ở tuần 3 chỉ phải sửa module này | G23: Chưa làm | J23: F2
A24: W1-P5 | B24: Prototype | C24: Chạy lại kịch bản demo 5 phút; commit phần đang sửa dở | D24: Huy | E24: 0 lỗi console trên Chrome và điện thoại | F24: Tự chạy theo README prototype | G24: Chưa làm
A25: KHUNG MVP — backend chạy được đường XML
A26: W1-B1 | B26: MVP | C26: Chốt schema Pydantic ExtractionResult và ReconciliationResult (có extras, loại dòng) | D26: Giáp | E26: 3/3 người còn lại đồng ý | F26: Schema có trong code và TEAM_PLAN mục 2 | G26: Chưa làm | J26: G1
A27: W1-B2 | B27: MVP | C27: Gộp feat/base_module và feat/iam về nhánh chính | D27: Giáp | E27: CI xanh | F27: Link CI | G27: Chưa làm | J27: G2
A28: W1-B3 | B28: MVP | C28: Schema DB: mọi bảng nghiệp vụ có org_id; migration chạy trên PostgreSQL 18 | D28: Giáp | E28: Test cách ly tenant trả 404: đạt | F28: Test tích hợp | G28: Chưa làm | J28: G3
A29: W1-B4 | B29: MVP | C29: Đăng nhập 2 vai trò kế toán viên, kế toán trưởng | D29: Giáp | E29: Gọi endpoint cấp 2 bằng token kế toán viên trả 403 | F29: Test tự động | G29: Chưa làm | J29: G3
A30: W1-B5 | B30: MVP | C30: Parser XML hóa đơn điện tử, cả khối TTKhac vào extras | D30: Dương | E30: 50/50 XML từ W1-D1 đi từ tải lên đến EXTRACTED | F30: Harness W1-M1 | G30: Chưa làm | J30: D2
A31: W1-B6 | B31: MVP | C31: Gỡ bút toán khỏi code (module ledger, trạng thái POSTED → EXPORTED) | D31: Giáp | E31: 0 bảng, 0 endpoint bút toán | F31: Tìm trong code | G31: Chưa làm | J31: G9
A32: W1-B7 | B32: MVP | C32: Deploy thử API | D32: Giáp | E32: Live URL trả được endpoint health | F32: Mở link | G32: Chưa làm | J32: G8
A33: CHỐT QUYẾT ĐỊNH — không chốt thì tuần 2 bị chặn
A34: W1-C1 | B34: Quyết định | C34: Được gửi hóa đơn thật lên dịch vụ nào | D34: Huy | E34: Có quyết định bằng văn bản | F34: Ghi vào PRD §14.2 | G34: Chưa làm | J34: U2, D1
A35: W1-C2 | B35: Quyết định | C35: Giới hạn trang mỗi file: 10 hay 20 | D35: Huy | E35: Một con số trong PRD F16 | F35: PRD và TEAM_PLAN khớp nhau | G35: Chưa làm | J35: U5
A36: W1-C3 | B36: Quyết định | C36: Nhóm thuế của các mặt hàng Công ty X hay mua | D36: Huy | E36: Danh sách nhóm hàng → thuế suất, rà theo phụ lục nghị định | F36: Điền vào tax_groups.yaml | G36: Chưa làm | J36: U2, H5
A37: W1-C4 | B37: Quyết định | C37: Báo cáo tuần 1 và nhật ký công việc | D37: Huy | E37: Nộp đúng hạn ở P-143 | F37: JOURNAL.md, WORKLOG.md | G37: Chưa làm | J37: P1

Sheet Backlog
A1: ID | B1: Nhóm việc | C1: Việc | D1: Người làm | E1: Tuần | F1: Ưu tiên | G1: Trạng thái | H1: % xong | I1: Hạn | J1: Điều kiện xong | K1: Cần từ ai | L1: Link PR / bằng chứng | M1: Ghi chú / vướng mắc | N1: Cập nhật lần cuối
A2: U1 | B2: BA | C2: Cập nhật PRD theo 13 việc ở Phụ lục A của RESEARCH.md | D2: Huy | E2: 2 | F2: M | G2: Đang làm | H2: 0 | J2: PRD có mục đầu vào và hóa đơn dài, mã ngoại lệ cho MST người mua, thuế 8% có ngày kết thúc
A3: U2 | B3: BA | C3: Chốt câu hỏi mở với mentor hoặc Công ty X: Q1–Q6 trong USER_STORIES.md, đầu vào (một file nhiều hóa đơn? bảng kê?), dung sai, ngưỡng duyệt cấp 2, nhóm thuế của mặt hàng Công ty X | D3: Huy | E3: 2 | F3: M | G3: Chưa làm | H3: 0 | J3: Mỗi câu có quyết định và ngày chốt, ghi vào PRD | K3: Mentor
A4: U3 | B4: BA | C4: Kịch bản kiểm thử chấp nhận từ 18 tình huống trong USER_STORIES.md; tổ chức buổi dùng thử với kế toán | D4: Huy | E4: 4 | F4: M | G4: Chưa làm | H4: 0 | J4: Biên bản buổi dùng thử, có số đo thời gian đối chiếu trước và sau — mục tiêu giảm 50%
A5: U4 | B5: BA | C5: Quy trình kiểm tra ngẫu nhiên hóa đơn đã xếp Khớp | D5: Huy | E5: Sau | F5: Sau | G5: Chưa làm | H5: 0 | J5: Tỉ lệ lấy mẫu, ai kiểm, ghi kết quả ở đâu
A6: U5 | B6: BA | C6: Chốt giới hạn trang mỗi file: limits.yaml cho 10 trang, việc D5 đặt mục tiêu 20 trang | D6: Huy | E6: 2 | F6: M | G6: Chưa làm | H6: 0 | J6: Một con số thống nhất trong PRD F16 và TEAM_PLAN D5 | K6: Dương
A7: P1 | B7: PM | C7: Kế hoạch tuần, báo cáo tuần cho mentor (JOURNAL.md), nhật ký công việc (WORKLOG.md) | D7: Huy | E7: Hằng tuần | F7: M | G7: Chưa làm | H7: 0 | J7: Nộp đúng hạn, ở P-143 | K7: Cả nhóm
A8: P2 | B8: PM | C8: Theo dõi checklist 10 deliverables của Demo Day | D8: Huy | E8: Từ tuần 2 | F8: M | G8: Chưa làm | H8: 0 | J8: Mỗi deliverable có người chịu trách nhiệm và hạn
A9: P3 | B9: PM | C9: Việc với mentor và ban tổ chức: xin dữ liệu mẫu, xác nhận Langfuse đáp ứng AI Logs, xin credit Google Cloud nếu dùng Document AI | D9: Huy | E9: 2 | F9: M | G9: Chưa làm | H9: 0 | J9: Có câu trả lời bằng văn bản | K9: Mentor
A10: P4 | B10: PM | C10: Theo dõi bảng rủi ro trong BRIEF_v3.md §13; quyết thứ tự cắt khi trễ | D10: Huy | E10: Hằng tuần | F10: M | G10: Chưa làm | H10: 0 | J10: Rủi ro cập nhật trong báo cáo tuần
A11: P5 | B11: PM | C11: Pitch deck 10 slide theo cấu trúc ban tổ chức và video demo tối đa 5 phút | D11: Huy | E11: 5 | F11: M | G11: Chưa làm | H11: 0 | J11: Nằm trong presentation/ của P-143 | K11: Cả nhóm
A12: F1 | B12: Frontend | C12: Đăng nhập thật bằng JWT, tự làm mới token khi hết hạn | D12: Huy | E12: 3 | F12: M | G12: Chưa làm | H12: 0 | J12: Hai vai trò đăng nhập được; token hết hạn thì tự làm mới | K12: Giáp
A13: F2 | B13: Frontend | C13: Thay dữ liệu mẫu bằng lời gọi API theo PRD §8: danh sách, so sánh ba chiều, ngoại lệ, duyệt, trả lại, từ chối, hàng đợi duyệt, nhà cung cấp | D13: Huy | E13: 3 | F13: M | G13: Chưa làm | H13: 0 | J13: Đi hết kịch bản demo trên dữ liệu từ API; không còn dữ liệu mẫu | K13: Giáp
A14: F3 | B14: Frontend | C14: Tải lên nhiều file và theo dõi tiến độ lô | D14: Huy | E14: 3 | F14: M | G14: Chưa làm | H14: 0 | J14: Thấy từng file đổi trạng thái; file trùng và file vượt giới hạn hiện đúng thông báo | K14: Giáp
A15: F4 | B15: Frontend | C15: Thông báo theo mã lỗi 401, 403, 404, 409, 413, 429; trạng thái đang tải và trạng thái rỗng | D15: Huy | E15: 4 | F15: M | G15: Chưa làm | H15: 0 | J15: Mỗi mã lỗi có câu thông báo nói rõ chuyện gì xảy ra và làm gì tiếp
A16: F5 | B16: Frontend | C16: Hóa đơn dài: mặc định chỉ hiện dòng lệch; chỉ tô vùng bằng chứng khi bbox_verified | D16: Huy | E16: 4 | F16: M | G16: Chưa làm | H16: 0 | J16: Hóa đơn 200 dòng vẫn mở nhanh; vùng chưa xác minh không được tô | K16: Dương
A17: F6 | B17: Frontend | C17: Deploy giao diện, cấu hình CORS với API | D17: Huy | E17: 4 | F17: M | G17: Chưa làm | H17: 0 | J17: Có live URL cho giao diện | K17: Giáp
A18: F7 | B18: Frontend | C18: Chuyển giao diện sang React, dùng lại module gọi API và bộ màu | D18: Huy | E18: Sau | F18: Sau | G18: Chưa làm | H18: 0 | J18: Chạy đủ kịch bản demo như bản HTML
A19: F8 | B19: Frontend | C19: Đổi tab Bút toán trong prototype thành Tóm tắt duyệt; trạng thái cuối là Đã xuất cho kế toán (PRD F10, WIREFRAME S7) | D19: Huy | E19: 3 | F19: M | G19: Chưa làm | H19: 0 | J19: Prototype không còn bút toán hay tài khoản Nợ, Có
A20: D1 | B20: Đọc hóa đơn | C20: So sánh hai đường đọc: Gemini 3.1 Flash-Lite mức MEDIUM và Document AI, trên cùng 30 hóa đơn scan | D20: Dương | E20: 2 | F20: M | G20: Chưa làm | H20: 0 | J20: Bảng so sánh độ chính xác, tỉ lệ sai mà không gắn cờ, chi phí mỗi trang, thời gian — và một quyết định ghi vào ADR | K20: Huy (được gửi dữ liệu lên đâu)
A21: D2 | B21: Đọc hóa đơn | C21: Bộ đọc PDF có chữ và bộ đọc ảnh, cài sau interface InvoiceExtractor | D21: Dương | E21: 2 | F21: M | G21: Chưa làm | H21: 0 | J21: PDF và ảnh không còn rơi vào FAILED với mã UNSUPPORTED_FORMAT; có unit test | K21: Giáp (gateway)
A22: D3 | B22: Đọc hóa đơn | C22: Chuẩn hóa kiểu: dấu chấm, dấu phẩy bằng số học; ngày viết bằng chữ; sửa nhầm lẫn OCR trong MST | D22: Dương | E22: 2 | F22: M | G22: Chưa làm | H22: 0 | J22: Test phủ ca 1.234 và 1,500, ngày dạng "Ngày 18 tháng 09 năm 2026"
A23: D4 | B23: Đọc hóa đơn | C23: Tách hóa đơn trong file nhiều trang — trang đầu, giữa, cuối, bảng kê | D23: Dương | E23: 3 | F23: M | G23: Chưa làm | H23: 0 | J23: Đo độ chính xác tách trên bộ file ghép; đoạn không chắc thì chuyển người
A24: D5 | B24: Đọc hóa đơn | C24: Bảng qua nhiều trang: mang tiêu đề theo, chia lô theo dòng, kiểm STT liền mạch, nhận cột bằng SL × đơn giá = thành tiền | D24: Dương | E24: 3 | F24: M | G24: Chưa làm | H24: 0 | J24: Hóa đơn nhiều trang, 200 dòng đọc đủ dòng, STT không đứt | K24: Huy (U5)
A25: D6 | B25: Đọc hóa đơn | C25: Độ tin cậy từng trường và hiệu chỉnh ngưỡng trên bộ đánh giá | D25: Dương | E25: 3–4 | F25: M | G25: Chưa làm | H25: 0 | J25: Ngưỡng do dữ liệu chọn; sai mà không gắn cờ ≈ 0
A26: D7 | B26: Đọc hóa đơn | C26: Xác minh bounding box: cắt vùng, đọc lại bằng Tesseract tiếng Việt, so với giá trị | D26: Dương | E26: 4 | F26: M | G26: Chưa làm | H26: 0 | J26: Báo được tỉ lệ bbox xác minh được
A27: D8 | B27: Đọc hóa đơn | C27: Dữ liệu hình ảnh cho đánh giá: render XML thành PDF và ảnh scan có nhiễu, cộng dữ liệu cào, cộng file ghép nhiều hóa đơn | D27: Dương | E27: 2–3 | F27: M | G27: Chưa làm | H27: 0 | J27: Ít nhất 100 ảnh có đáp án đúng | K27: Hoàn (XML từ H1)
A28: D9 | B28: Đọc hóa đơn | C28: Chạy thử mô hình mở — DeepSeek-OCR 2, Qwen3-VL, PaddleOCR-VL — trên cùng bộ đánh giá | D28: Dương | E28: Sau | F28: Sau | G28: Chưa làm | H28: 0 | J28: Bảng so với đường API | K28: Máy có GPU
A29: H1 | B29: Đối chiếu & an toàn AI | C29: Bộ sinh dữ liệu: XML hóa đơn, PO và phiếu nhập tương ứng, cài sẵn các kiểu lệch có nhãn | D29: Hoàn | E29: 2 | F29: M | G29: Chưa làm | H29: 0 | J29: 300 bộ có đáp án mã ngoại lệ đúng, phân bổ theo PRD §12.1
A30: H2 | B30: Đối chiếu & an toàn AI | C30: Kiểm MST: chữ số kiểm tra dạng 10 và 13 số (stdnum.vn.mst); dạng 12 số; MST người mua bằng MST công ty; MST người bán khớp danh mục | D30: Hoàn | E30: 2 | F30: M | G30: Chưa làm | H30: 0 | J30: Test với MST thật, ca sai một chữ số và đảo hai chữ số
A31: H3 | B31: Đối chiếu & an toàn AI | C31: Khớp dòng L0 đến L3: mã hàng, bộ nhớ NCC, chuỗi chuẩn hóa, so chuỗi gần đúng | D31: Hoàn | E31: 2–3 | F31: M | G31: Chưa làm | H31: 0 | J31: Đo recall khớp dòng trên bộ đánh giá | K31: Dương (ExtractionResult)
A32: H4 | B32: Đối chiếu & an toàn AI | C32: Khớp dòng L4: LlmArbiter, chỉ được chọn trong danh sách ứng viên | D32: Hoàn | E32: 3 | F32: M | G32: Chưa làm | H32: 0 | J32: Đếm được số lần gọi mô hình mỗi hóa đơn | K32: Giáp (gateway)
A33: H5 | B33: Đối chiếu & an toàn AI | C33: Kiểm thuế: vat_rates.yaml (8% hết hạn 31/12/2026), tax_groups.yaml, dòng KCT không có thuế, hóa đơn bán hàng; TAX-01 đến TAX-05 | D33: Hoàn | E33: 3 | F33: M | G33: Chưa làm | H33: 0 | J33: Test ví dụ PRD §6 và các ca sát mốc 30/6–01/7/2025, 31/12/2026–01/01/2027 | K33: Huy (nhóm thuế ở U2)
A34: H6 | B34: Đối chiếu & an toàn AI | C34: Phân loại, đề xuất xử lý, viết giải thích chỉ từ dữ kiện có cấu trúc | D34: Hoàn | E34: 3 | F34: M | G34: Chưa làm | H34: 0 | J34: Mọi ngoại lệ có công thức và nguồn; chữ chứa lệnh trên hóa đơn không lọt vào câu giải thích
A35: H7 | B35: Đối chiếu & an toàn AI | C35: Phát hiện bất thường FRD-01 đến FRD-07, so lớp chữ PDF với ảnh render ở trường tiền | D35: Hoàn | E35: 4 | F35: S | G35: Chưa làm | H35: 0 | J35: Recall các ca gian lận đã cài ≥ 95% | K35: Dương
A36: H8 | B36: Đối chiếu & an toàn AI | C36: Bộ nhớ NCC: học tên gọi khác từ lần sửa, chỉ hiệu lực khi KTT duyệt | D36: Hoàn | E36: 4 | F36: S | G36: Chưa làm | H36: 0 | J36: Hóa đơn thứ tư cùng NCC khớp ở L1 và không gọi mô hình
A37: H9 | B37: Đối chiếu & an toàn AI | C37: Thử mô hình gác Llama Prompt Guard 2 trên câu tấn công tiếng Việt | D37: Hoàn | E37: Sau | F37: Sau | G37: Chưa làm | H37: 0 | J37: Báo cáo tỉ lệ bỏ sót, kết luận dùng hay không
A38: G1 | B38: Backend & nền tảng | C38: Chốt hợp đồng bàn giao ExtractionResult, ReconciliationResult thành schema Pydantic (có extras và loại dòng) | D38: Giáp | E38: 2 | F38: M | G38: Chưa làm | H38: 0 | J38: Có trong code và tài liệu, ba người còn lại đồng ý | K38: Dương, Hoàn
A39: G2 | B39: Backend & nền tảng | C39: Gộp feat/base_module và feat/iam về nhánh chính | D39: Giáp | E39: 2 | F39: M | G39: Chưa làm | H39: 0 | J39: Nhánh chính chạy được, CI xanh
A40: G3 | B40: Backend & nền tảng | C40: Nối module vào API theo PRD §8: tải lên, nhập PO và phiếu nhập, đối chiếu, duyệt hai cấp, xuất danh sách hóa đơn đã duyệt, nhật ký, báo cáo | D40: Giáp | E40: 2–3 | F40: M | G40: Chưa làm | H40: 0 | J40: Đi hết luồng bằng API; test tách biệt trách nhiệm (409) và cách ly tenant (404)
...

Sheet Tổng quan
A1: TIẾN ĐỘ THEO NGƯỜI
A2: Chỉ tính việc ưu tiên M và S; việc "Sau" không tính. Tự cập nhật từ sheet Backlog.
A4: Người | B4: Chưa làm | C4: Đang làm | D4: Chờ review | E4: Bị chặn | F4: Xong | G4: Tổng | H4: % việc xong | I4: Việc quá hạn
A5: Huy | B5: =COUNTIFS(Backlog!$D$2:$D$300,$A5,Backlog!$G$2:$G$300,"Chưa làm",Backlog!$F$2:$F$300,"<>Sau") | C5: =COUNTIFS(Backlog!$D$2:$D$300,$A5,Backlog!$G$2:$G$300,"Đang làm",Backlog!$F$2:$F$300,"<>Sau") | D5: =COUNTIFS(Backlog!$D$2:$D$300,$A5,Backlog!$G$2:$G$300,"Chờ review",Backlog!$F$2:$F$300,"<>Sau") | E5: =COUNTIFS(Backlog!$D$2:$D$300,$A5,Backlog!$G$2:$G$300,"Bị chặn",Backlog!$F$2:$F$300,"<>Sau") | F5: =COUNTIFS(Backlog!$D$2:$D$300,$A5,Backlog!$G$2:$G$300,"Xong",Backlog!$F$2:$F$300,"<>Sau") | G5: =SUM(B5:F5) | H5: =IF(G5=0,0,F5/G5) | I5: =COUNTIFS(Backlog!$D$2:$D$300,$A5,Backlog!$I$2:$I$300,"<"&TODAY(),Backlog!$I$2:$I$300,"<>",Backlog!$G$2:$G$300,"<>Xong")
A6: Dương | B6: =COUNTIFS(Backlog!$D$2:$D$300,$A6,Backlog!$G$2:$G$300,"Chưa làm",Backlog!$F$2:$F$300,"<>Sau") | C6: =COUNTIFS(Backlog!$D$2:$D$300,$A6,Backlog!$G$2:$G$300,"Đang làm",Backlog!$F$2:$F$300,"<>Sau") | D6: =COUNTIFS(Backlog!$D$2:$D$300,$A6,Backlog!$G$2:$G$300,"Chờ review",Backlog!$F$2:$F$300,"<>Sau") | E6: =COUNTIFS(Backlog!$D$2:$D$300,$A6,Backlog!$G$2:$G$300,"Bị chặn",Backlog!$F$2:$F$300,"<>Sau") | F6: =COUNTIFS(Backlog!$D$2:$D$300,$A6,Backlog!$G$2:$G$300,"Xong",Backlog!$F$2:$F$300,"<>Sau") | G6: =SUM(B6:F6) | H6: =IF(G6=0,0,F6/G6) | I6: =COUNTIFS(Backlog!$D$2:$D$300,$A6,Backlog!$I$2:$I$300,"<"&TODAY(),Backlog!$I$2:$I$300,"<>",Backlog!$G$2:$G$300,"<>Xong")
A7: Hoàn | B7: =COUNTIFS(Backlog!$D$2:$D$300,$A7,Backlog!$G$2:$G$300,"Chưa làm",Backlog!$F$2:$F$300,"<>Sau") | C7: =COUNTIFS(Backlog!$D$2:$D$300,$A7,Backlog!$G$2:$G$300,"Đang làm",Backlog!$F$2:$F$300,"<>Sau") | D7: =COUNTIFS(Backlog!$D$2:$D$300,$A7,Backlog!$G$2:$G$300,"Chờ review",Backlog!$F$2:$F$300,"<>Sau") | E7: =COUNTIFS(Backlog!$D$2:$D$300,$A7,Backlog!$G$2:$G$300,"Bị chặn",Backlog!$F$2:$F$300,"<>Sau") | F7: =COUNTIFS(Backlog!$D$2:$D$300,$A7,Backlog!$G$2:$G$300,"Xong",Backlog!$F$2:$F$300,"<>Sau") | G7: =SUM(B7:F7) | H7: =IF(G7=0,0,F7/G7) | I7: =COUNTIFS(Backlog!$D$2:$D$300,$A7,Backlog!$I$2:$I$300,"<"&TODAY(),Backlog!$I$2:$I$300,"<>",Backlog!$G$2:$G$300,"<>Xong")
A8: Giáp | B8: =COUNTIFS(Backlog!$D$2:$D$300,$A8,Backlog!$G$2:$G$300,"Chưa làm",Backlog!$F$2:$F$300,"<>Sau") | C8: =COUNTIFS(Backlog!$D$2:$D$300,$A8,Backlog!$G$2:$G$300,"Đang làm",Backlog!$F$2:$F$300,"<>Sau") | D8: =COUNTIFS(Backlog!$D$2:$D$300,$A8,Backlog!$G$2:$G$300,"Chờ review",Backlog!$F$2:$F$300,"<>Sau") | E8: =COUNTIFS(Backlog!$D$2:$D$300,$A8,Backlog!$G$2:$G$300,"Bị chặn",Backlog!$F$2:$F$300,"<>Sau") | F8: =COUNTIFS(Backlog!$D$2:$D$300,$A8,Backlog!$G$2:$G$300,"Xong",Backlog!$F$2:$F$300,"<>Sau") | G8: =SUM(B8:F8) | H8: =IF(G8=0,0,F8/G8) | I8: =COUNTIFS(Backlog!$D$2:$D$300,$A8,Backlog!$I$2:$I$300,"<"&TODAY(),Backlog!$I$2:$I$300,"<>",Backlog!$G$2:$G$300,"<>Xong")
A9: Cả nhóm | B9: =SUM(B5:B8) | C9: =SUM(C5:C8) | D9: =SUM(D5:D8) | E9: =SUM(E5:E8) | F9: =SUM(F5:F8) | G9: =SUM(B9:F9) | H9: =IF(G9=0,0,F9/G9) | I9: =SUM(I5:I8)
A11: Cột "Bị chặn" và "Việc quá hạn" lớn hơn 0 sẽ tô đỏ — đem ra đầu buổi họp nhóm.

Sheet Họp tuần
A1: Tuần | B1: Ngày họp | C1: Đã xong tuần này | D1: Kế hoạch tuần tới | E1: Vướng mắc / cần ai giúp | F1: Quyết định đã chốt
A2: 2 | B2: 46291.708 | C2: VÍ DỤ — xóa dòng này khi dùng thật. U1 cập nhật PRD: bỏ bút toán, thêm nhóm thuế và hạn thuế 8% | D2: G1 chốt schema ExtractionResult; D1 so sánh Gemini và Document AI | E2: D1 chờ Huy chốt được gửi hóa đơn thật lên dịch vụ nào | F2: Hệ thống không sinh bút toán (TEAM_PLAN mục 5, quyết định 5)
